<?xml version="1.0"?>
<robot name="garbo"
  xmlns:xacro="http://ros.org/wiki/xacro">

<!-- Define some commonly used intertial properties  -->
  <xacro:macro name="box_inertia" params="m w h d">
    <inertial>
      <origin xyz="0 0 0" rpy="${pi/2} 0 ${pi/2}"/>
      <mass value="${m}"/>
      <inertia ixx="${(m/12) * (h*h + d*d)}" ixy="0.0" ixz="0.0" iyy="${(m/12) * (w*w + d*d)}" iyz="0.0" izz="${(m/12) * (w*w + h*h)}"/>
    </inertial>
  </xacro:macro>

  <xacro:macro name="cylinder_inertia" params="m r h">
    <inertial>
      <origin xyz="0 0 0" rpy="${pi/2} 0 0" />
      <mass value="${m}"/>
      <inertia ixx="${(m/12) * (3*r*r + h*h)}" ixy = "0" ixz = "0" iyy="${(m/12) * (3*r*r + h*h)}" iyz = "0" izz="${(m/2) * (r*r)}"/>
    </inertial>
  </xacro:macro>

  <xacro:macro name="sphere_inertia" params="m r">
    <inertial>
      <mass value="${m}"/>
      <inertia ixx="${(2/5) * m * (r*r)}" ixy="0.0" ixz="0.0" iyy="${(2/5) * m * (r*r)}" iyz="0.0" izz="${(2/5) * m * (r*r)}"/>
    </inertial>
  </xacro:macro>


  <!-- Define robot constants -->
  <xacro:property name="base_width" value="0.35"/>
  <xacro:property name="base_length" value="0.7"/>
  <xacro:property name="base_height" value="0.15"/>
  <xacro:property name="base_mass" value="10"/>

  <xacro:property name="wheel_radius" value="0.127"/>
  <xacro:property name="wheel_width" value="0.075"/>
  <xacro:property name="wheel_ygap" value="0.0"/><!--Gap between body and wheel-->
  <xacro:property name="wheel_zoff" value="0.0"/><!--Use if center of wheel isnt at bottom of base/-->
  <xacro:property name="wheel_xoff" value="0.0"/><!--Set at 0.0 so wheels are inline with base origin/center of rotation-->
  <xacro:property name="wheel_mass" value="1"/>

   <xacro:property name="caster_radius" value="0.0635"/> <!--Wheel radius/2, as a number for inertia calcs-->
   <xacro:property name="caster_Xoffset" value="${base_length - wheel_radius - caster_radius}"/>
   <xacro:property name="caster_Yoffset" value="${base_width/2 - caster_radius}"/>
   <xacro:property name="caster_Zoffset" value="${-wheel_radius/2}"/>
   <xacro:property name="caster_mass" value="0.5"/>

  
  <!-- Robot Base -->
   <!--Origin point of the robot-->
  <link name="base_link">
  </link>


  <!-- Robot Footprint -->
  <!--The base location in flat 2D since the robot will be changing elevation-->
  <link name="base_footprint">
  </link>

  <joint name="base_joint" type="fixed">
    <parent link="base_link"/>
    <child link="base_footprint"/>
    <origin xyz="0.0 0.0 ${-(wheel_radius+wheel_zoff)}" rpy="0 0 0"/>
  </joint>



<!-- Chassis -->
  <joint name="chassis_joint" type="fixed">
    <parent link="base_link"/>
    <child link="chassis"/>
    <origin xyz="${-wheel_radius} 0 0"/>
    </joint>

    <link name="chassis">
      <visual>
        <geometry>
          <box size="${base_length} ${base_width} ${base_height}"/>
        </geometry>
        <material name="white"/>
      </visual>
      <collision>
        <geometry>
          <box size="${base_length} ${base_width} ${base_height}"/>
        </geometry>
      </collision>
      <xacro:inertial_box mass="${base_mass}" x="${base_length}" y="${base_width}" z="${base_height}">
      </xacro:inertial_box>
    </link>




<!-- Drive Wheels -->
 <!--Centered along base_link Y axis-->
  <xacro:macro name="wheel" params="prefix x_reflect y_reflect">
    <link name="${prefix}_link">
      <visual>
        <origin xyz="0 0 0" rpy="${pi/2} 0 0"/>
        <geometry>
          <cylinder radius="${wheel_radius}" length="${wheel_width}"/>
        </geometry>
        <material name="Gray">
          <color rgba="0.5 0.5 0.5 1.0"/>
        </material>
      </visual>

      <collision>
        <origin xyz="0 0 0" rpy="${pi/2} 0 0"/>
        <geometry>
          <cylinder radius="${wheel_radius}" length="${wheel_width}"/>
        </geometry>
      </collision>

      <xacro:cylinder_inertia m="${wheel_mass}" r="${wheel_radius}" h="${wheel_width}"/>
    </link>

    <joint name="${prefix}_joint" type="continuous">
      <parent link="base_link"/>
      <child link="${prefix}_link"/>
      <origin xyz="${x_reflect*wheel_xoff} ${y_reflect*(base_width/2 + wheel_ygap + wheel_width/2)} ${-wheel_zoff}" rpy="0 0 0"/>
      <axis xyz="0 1 0"/>
    </joint>
  </xacro:macro>

  <xacro:wheel prefix="drivewhl_l" x_reflect="-1" y_reflect="1" />
  <xacro:wheel prefix="drivewhl_r" x_reflect="-1" y_reflect="-1" />




<!-- Caster Wheels -->
  <xacro:macro name="caster" params="prefix x_reflect y_reflect">
    <link name="${prefix}_link">
      <visual>
        <origin xyz="0 0 0" rpy="0 0 0"/>
        <geometry>
            <sphere radius="${caster_radius}" />
        </geometry>
        <material name="Gray">
          <color rgba="0.5 0.5 0.5 1.0"/>
        </material>
      </visual>

      <collision>
        <origin xyz="0 0 0" rpy="0 0 0"/>
        <geometry>
            <sphere radius="${caster_radius}" />
        </geometry>
      </collision>

      <xacro:sphere_inertia m="${caster_mass}" r="${caster_radius}">
        <origin xyz="0 0 0" rpy="0 0 0"/>
      </xacro:sphere_inertia>
    </link>

    <joint name="${prefix}_joint" type="fixed">
      <parent link="base_link"/>
      <child link="${prefix}_link"/>
      <origin xyz="${x_reflect*caster_Xoffset} ${y_reflect*caster_Yoffset} ${caster_Zoffset}" rpy="0 0 0"/>
    </joint>
  </xacro:macro>

  <xacro:caster prefix="casterwhl_l" x_reflect="1" y_reflect="1" />
  <xacro:caster prefix="casterwhl_r" x_reflect="1" y_reflect="-1" />




<!--IMU Sensor-->
  <link name="imu_link">
    <visual>
      <geometry>
        <box size="0.1 0.1 0.1"/>
      </geometry>
    </visual>

    <collision>
      <geometry>
        <box size="0.1 0.1 0.1"/>
      </geometry>
    </collision>

    <xacro:box_inertia m="0.1" w="0.1" d="0.1" h="0.1"/>
  </link>

  <joint name="imu_joint" type="fixed">
    <parent link="base_link"/>
    <child link="imu_link"/>
    <origin xyz="0 0 0.01"/>
  </joint>




<!-- LIDAR Sensor -->
  <link name="lidar_link">
    <inertial>
      <origin xyz="0 0 0" rpy="0 0 0"/>
      <mass value="0.125"/>
      <inertia ixx="0.001" ixy="0" ixz="0" iyy="0.001" iyz="0" izz="0.001" />
    </inertial>

    <collision>
      <origin xyz="0 0 0" rpy="0 0 0"/>
      <geometry>
        <cylinder radius="0.0508" length="0.055"/>
      </geometry>
    </collision>

    <visual>
      <origin xyz="0 0 0" rpy="0 0 0"/>
      <geometry>
        <cylinder radius="0.0508" length="0.055"/>
      </geometry>
    </visual>
  </link>

  <joint name="lidar_joint" type="fixed">
    <parent link="base_link"/>
    <child link="lidar_link"/>
    <origin xyz="${base_length - wheel_radius - 0.0508} 0  ${base_height + 0.0275}" rpy="0 0 0"/>
  </joint>




<!--Depth Camera Sensor-->
  <link name="depth_camera_link">
    <visual>
      <origin xyz="0 0 0" rpy="0 0 0"/>
      <geometry>
        <box size="0.01 0.03 0.03"/>
      </geometry>
    </visual>

    <collision>
      <origin xyz="0 0 0" rpy="0 0 0"/>
      <geometry>
        <box size="0.01 0.03 0.03"/>
      </geometry>
    </collision>

    <inertial>
      <origin xyz="0 0 0" rpy="0 0 0"/>
      <mass value="0.035"/>
      <inertia ixx="0.001" ixy="0" ixz="0" iyy="0.001" iyz="0" izz="0.001" />
    </inertial>
  </link>

  <joint name="depth_camera_joint" type="fixed">
    <parent link="base_link"/>
    <child link="depth_camera_link"/>
    <origin xyz="${base_length - wheel_radius + 0.005} 0 0.1" rpy="0 0 0"/>
  </joint>




<!--Rear Camera Sensor-->
  <link name="rear_camera_link">
    <visual>
      <origin xyz="0 0 0" rpy="0 0 0"/>
      <geometry>
        <box size="0.01 0.03 0.03"/>
      </geometry>
    </visual>

    <collision>
      <origin xyz="0 0 0" rpy="0 0 0"/>
      <geometry>
        <box size="0.01 0.03 0.03"/>
      </geometry>
    </collision>

    <inertial>
      <origin xyz="0 0 0" rpy="0 0 0"/>
      <mass value="0.1"/>
      <inertia ixx="0.001" ixy="0" ixz="0" iyy="0.001" iyz="0" izz="0.001" />
    </inertial>
  </link>

  <joint name="rear_camera_joint" type="fixed">
    <parent link="base_link"/>
    <child link="rear_camera_link"/>
    <origin xyz="${-wheel_radius-0.01} 0 0.1" rpy="0 0 ${pi}"/> <!--Faces backwards-->
  </joint>


</robot>